Workbook

Sheet Water Baseline
A1: WATER DEMAND BASELINE
A3: WATER CONSUMPTION CALCULATIONS: | H3: TOILET DEMAND
A5: ACTIVITY | B5: Rate | C5: Frequency | D5: Time | E5: Person | F5: Litres/day | H5: MALE USE | I5: Rate | J5: Frequency | K5: person | L5: Litres/day | N5: Baseline Demand | O5: Litres/day
A6: Toilet Hand washing | B6: 4L/min | C6: 4 | D6: 0.5 | E6: 2000 | F6: =4*C6*D6*E6 -> 16000 | H6: Toilet flush | I6: 9 Litres | J6: 2 | K6: 1000 | L6: =9*J6*K6 -> 18000 | N6: Total Water Demand | O6: 81000
A7: Café Kitchen sink | B7: 6L/min | D7: 150 | F7: =D7*6 -> 900 | H7: Urinals | I7: 197m3/year | L7: 500 | N7: All Greywater Use | O7: 23700
A8: Kitchen Dishwasher | B8: 10L/cycle | C8: 150 | F8: =C8*10 -> 1500 | H8: FEMALE USE | N8: Toilet Water Use | O8: 54500
A9: Wet Lab water use | B9: 200L/day | F9: 200 | H9: Toilet flush | I9: 9 Litres | J9: 4 | K9: 1000 | L9: =9*J9*K9 -> 36000
A10: Cleaner use | B10: 100L/day | F10: 100 | H10: TOTAL | L10: =SUM(L6:L9) -> 54500
A11: Showers | B11: 10L/min | C11: 1 | D11: 5 | E11: =100 -> 100 | F11: =10*C11*D11*E11 -> 5000
A12: Drink water Station | B12: 2L/day/prs | E12: =2000*0.7 -> 1400 | F12: =2*E12 -> 2800
A13: TOTAL | F13: =SUM(F6:F12) -> 26500
I15: User Types
A16: COST CALCULATIONS: | I16: Researchers | J16: Office/Working staff
A17: Business Water Rate Northumbria water (Wholesale charges 25/26): | I17: Lab staff | J17: Receptionists
A18: Water Supply (per m3) | B18: =1.6336 -> 1.6336 | I18: Cleaners | J18: Caretakers
A19: Sewage Costs (per m3) | B19: 1.8797 | C19: Business Water Rates, Prices and Tariffs 2025 | I19: Students | J19: Other Staff
A20: Utility | B20: Daily Use | C20: Yearly Water | D20: Yearly Sewage | E20: Total cost/year | I20: Visitor
A21: Toilet flush | B21: 54500 | C21: =$B$18*(B21/1000)*365 -> 32496.388 | D21: =$B$19*(B21/1000)*365 -> 37391.932 | E21: =D21+C21 -> 69888.32
A22: Toilet hand basins | B22: 16000 | C22: =$B$18*(B22/1000)*365 -> 9540.224 | D22: =$B$19*(B22/1000)*365 -> 10977.448 | E22: =D22+C22 -> 20517.672
A23: Showers | B23: 5000 | C23: =$B$18*(B23/1000)*365 -> 2981.32 | D23: =$B$19*(B23/1000)*365 -> 3430.4525 | E23: =D23+C23 -> 6411.7725
A24: Wet Lab water Use | B24: 200 | C24: =$B$18*(B24/1000)*365 -> 119.2528 | D24: =$B$19*(B24/1000)*365 -> 137.2181 | E24: =D24+C24 -> 256.4709
A25: Drinking water | B25: 2800 | C25: =$B$18*(B25/1000)*365 -> 1669.5392 | D25: =$B$19*(B25/1000)*365 -> 1921.0534 | E25: =D25+C25 -> 3590.5926
A26: Café | B26: 2400 | C26: =$B$18*(B26/1000)*365 -> 1431.0336 | D26: =$B$19*(B26/1000)*365 -> 1646.6172 | E26: =D26+C26 -> 3077.6508
A27: Cleaners | B27: 100 | C27: =$B$18*(B27/1000)*365 -> 59.6264 | D27: =$B$19*(B27/1000)*365 -> 68.60905 | E27: =D27+C27 -> 128.23545
A28: TOTAL: | B28: =SUM(B21:B27) -> 81000 | C28: =SUM(C21:C27) -> 48297.384 | D28: =SUM(D21:D27) -> 55573.33 | E28: =SUM(E21:E27) -> 103870.71
A31: Hot Water Demand:

Sheet Water Intervention
A1: New Water Demand and Analysis
A3: WATER CONSUMPTION CALCULATIONS:
A5: ACTIVITY | B5: Rate | C5: Frequency | D5: Time | E5: Person | F5: Litres/day | H5: TOILET DEMAND
A6: Toilet Hand washing | B6: 2L/min | C6: 4 | D6: 0.5 | E6: 2000 | F6: =2*C6*D6*E6*0.85 -> 6800 | H6: MALE USE | I6: Rate | J6: Frequency | K6: Person | L6: Litres/day | O6: New Demand | P6: Litres/day | Q6: REDUCTIONS
A7: Café Kitchen sink | B7: 6L/min | D7: 150 | F7: =D7*6 -> 900 | H7: Toilet flush (Lrg) | I7: 6 Litres | J7: 1 | K7: =0.5*1000 -> 500 | L7: =K7*J7*6 -> 3000 | O7: Total Water Demand | P7: =L13+F13 -> 30250 | Q7: =(81000-P7)/81000 -> 0.62654321
A8: Kitchen Dishwasher | B8: 2L/cycle | C8: 150 | F8: =C8*2 -> 300 | H8: Toilet flush (Sml) | I8: 3 Litres | J8: 1 | K8: 50 | L8: =3*J8*K8 -> 150 | O8: All Greywater Use | P8: =SUM(F6:F11) -> 12300 | Q8: =(23700-P8)/23700 -> 0.48101266
A9: Wet Lab water use | F9: 200 | H9: Urinals | I9: 0 Litres | J9: 3 | K9: 950 | L9: 0 | O9: Toilet Water Use | P9: =L13 -> 15150 | Q9: =(54500-15150)/54500 -> 0.72201835
A10: Cleaner use | B10: 100L/day | F10: 100 | H10: FEMALE USE
A11: Showers | B11: 8 L/min | C11: 1 | D11: 5 | E11: 100 | F11: =8*C11*D11*E11 -> 4000 | H11: Toilet flush (Lrg) | I11: 6 Litres | J11: 1 | K11: =0.5*1000 -> 500 | L11: =K11*J11*6 -> 3000 | O11: Reusable Greywater (Showers and Sinks) | P11: =F11+F6 -> 10800
A12: Drink water Station | B12: 2L/day/prs | E12: =0.7*2000 -> 1400 | F12: =2*E12 -> 2800 | H12: Toilet flush (Sml) | I12: 3 Litres | J12: 3 | K12: 1000 | L12: =3*J12*K12 -> 9000
A13: TOTAL | F13: =SUM(F6:F12) -> 15100 | H13: TOTAL | L13: =SUM(L7:L12) -> 15150
A17: Simple ROI calculation of Capital Cost/Savings
A18: Prices From: | B18: Commercial Washrooms, Toilet refurbishments and Supplies
B19: Capital Cost | C19: Water savings per day (m3) | D19: Savings Per Year(£) | E19: ROI (Years)
A20: Dual Toilets | B20: =250*84 -> 21000 | C20: =(54000-15150)/1000 -> 38.85 | D20: =1.6336*365*C20 -> 23164.856 | E20: =B20/D20 -> 0.90654566 | F20: 11 months
A21: Showers | B21: =312*40 -> 12480 | C21: =1000/1000 -> 1 | D21: =1.6336*365*C21 -> 596.264 | E21: =B21/D21 -> 20.930326 | F21: 21 years
A22: Urinals | B22: =554*36 -> 19944 | C22: 0.5 | D22: =1.6336*365*C22 -> 298.132 | E22: =B22/D22 -> 66.896542
A23: Bathroom Taps | B23: =300*48 -> 14400 | C23: =(16000-6800)/1000 -> 9.2 | D23: =1.6336*365*C23 -> 5485.6288 | E23: =B23/D23 -> 2.6250409 | F23: up to 3 years
A24: AQUALOOP | B24: 60000 | D24: 8000 | E24: =B24/D24 -> 7.5 | F24: up to 8 years | G24: (assuming that maintence is twice a year at £500
A27: COST CALCULATIONS:
A28: Water | B28: =1.6336 -> 1.6336
A29: Sewage | B29: 1.8797
A30: Utility | B30: Daily Use | C30: Yearly Water | D30: Yearly Sewage | E30: Total cost/year | F30: Reductions | G30: Savings per Year
A31: Toilet flush | B31: 15150 | C31: =$B$28*(B31/1000)*365 -> 9033.3996 | D31: =$B$29*(B31/1000)*365 -> 10394.271 | E31: =D31+C31 -> 19427.671 | F31: =('Water Baseline'!B21-'Water Intervention'!B31)/'Water Baseline'!B21 -> 0.72201835 | G31: ='Water Baseline'!E21-'Water Intervention'!E31 -> 50460.65
A32: Toilet hand basins | B32: 6800 | C32: =$B$28*(B32/1000)*365 -> 4054.5952 | D32: =$B$29*(B32/1000)*365 -> 4665.4154 | E32: =D32+C32 -> 8720.0106 | F32: =('Water Baseline'!B22-'Water Intervention'!B32)/'Water Baseline'!B22 -> 0.575 | G32: ='Water Baseline'!E22-'Water Intervention'!E32 -> 11797.661
A33: Showers | B33: 4000 | C33: =$B$28*(B33/1000)*365 -> 2385.056 | D33: =$B$29*(B33/1000)*365 -> 2744.362 | E33: =D33+C33 -> 5129.418 | F33: =('Water Baseline'!B23-'Water Intervention'!B33)/'Water Baseline'!B23 -> 0.2 | G33: ='Water Baseline'!E23-'Water Intervention'!E33 -> 1282.3545
A34: Wet Lab water Use | B34: 200 | C34: =$B$28*(B34/1000)*365 -> 119.2528 | D34: =$B$29*(B34/1000)*365 -> 137.2181 | E34: =D34+C34 -> 256.4709 | F34: =('Water Baseline'!B24-'Water Intervention'!B34)/'Water Baseline'!B24 -> 0 | G34: ='Water Baseline'!E24-'Water Intervention'!E34 -> 0
A35: Drinking water | B35: 2800 | C35: =$B$28*(B35/1000)*365 -> 1669.5392 | D35: =$B$29*(B35/1000)*365 -> 1921.0534 | E35: =D35+C35 -> 3590.5926 | F35: =('Water Baseline'!B25-'Water Intervention'!B35)/'Water Baseline'!B25 -> 0 | G35: ='Water Baseline'!E25-'Water Intervention'!E35 -> 0
A36: Café | B36: 1200 | C36: =$B$28*(B36/1000)*365 -> 715.5168 | D36: =$B$29*(B36/1000)*365 -> 823.3086 | E36: =D36+C36 -> 1538.8254 | F36: =('Water Baseline'!B26-'Water Intervention'!B36)/'Water Baseline'!B26 -> 0.5 | G36: ='Water Baseline'!E26-'Water Intervention'!E36 -> 1538.8254
A37: Cleaners | B37: 100 | C37: =$B$28*(B37/1000)*365 -> 59.6264 | D37: =$B$29*(B37/1000)*365 -> 68.60905 | E37: =D37+C37 -> 128.23545 | F37: =('Water Baseline'!B27-'Water Intervention'!B37)/'Water Baseline'!B27 -> 0 | G37: ='Water Baseline'!E27-'Water Intervention'!E37 -> 0
A38: TOTAL: | B38: =SUM(B31:B37) -> 30250 | C38: =SUM(C31:C37) -> 18036.986 | D38: =SUM(D31:D37) -> 20754.238 | E38: =SUM(E31:E37) -> 38791.224 | F38: =('Water Baseline'!B28-'Water Intervention'!B38)/'Water Baseline'!B28 -> 0.62654321 | G38: =SUM(G31:G37) -> 65079.491
A41: Efficiency of Devices
A43: Fittings | B43: Coventional | C43: Chosen Alternative | D43: Device Reductions %
A44: Toilets | B44: 6-9L/flush | C44: 6 or 3L/flush | D44: up to 50%
A45: Showers | B45: 10L/min | C45: 8L/min | D45: 0.2
A46: Dishwashers | B46: 10L/cycle | C46: 2L/cycle | D46: 0.8
A47: Urinals | B47: L/day | C47: 0L/min | D47: 1
A48: Bathroom Taps | B48: 4L/min | C48: 2L/min | D48: 0.5

Sheet Energy Baseline 
B3: Area | C3: Volume | D3: Maximum Occupancy | F3: Computers | G3: Cookers/Ovens/Stoves | J3: 24hrs and 365 days basis
J4: Total Lighting | K4: Total cookers/Ovens/Stoves | L4: Total Water Heating | M4: Total Computers | N4: Total Heating | O4: Total ventilation | P4: Total Showers | Q4: Total Cooling
A5: Lifts | J5: =10800*(1/0.092903)*7 -> 813751.98 | K5: =G73 -> 31966 | L5: =10800*(1/0.092903)*0.5 -> 58125.141 | M5: =F73 -> 309444.2 | N5: =10800*(1/0.092903)*2*(8/12) -> 155000.38 | O5: =10800*(1/0.092903)*2 -> 232500.57 | Q5: =10800*(1/0.092903)*3*(4/12) -> 116250.28
J7: Total
A8: Ground Floor | J8: =SUM(J5:R5) -> 1717038.5
A10: Café | B10: 180 | C10: =B10*4.5 -> 810 | D10: 90 | J10: 12hrs and 365 days basis
A11: Library | B11: 210 | C11: =B11*(4.5) -> 945 | D11: 70 | F11: =1.7*365*35 -> 21717.5 | J11: Total Lighting | K11: Total cookers/Ovens/Stoves | L11: Total Water Heating | M11: Total Computers | N11: Total Heating | O11: Total ventilation | P11: Total Showers | Q11: Total Cooling
A12: Events | B12: 98 | C12: =B12*(4.5) -> 441 | D12: 200 | J12: =1/2*J5 -> 406875.99 | K12: =K5 -> 31966 | L12: =1/2*L5 -> 29062.571 | M12: =M5 -> 309444.2 | N12: =1/2*N5 -> 77500.188 | O12: =1/2*O5 -> 116250.28 | Q12: =1/2*Q5 -> 58125.141
A13: Kitchen | B13: 28 | C13: =B13*(4.5) -> 126 | D13: 4 (Staff) | G13: =15*253*8 -> 30360
A14: Servery | B14: 10 | C14: =B14*(4.5) -> 45 | D14: 2 (Staff) | J14: Total
A15: Reception Desk | B15: 8 | C15: =B15*(4.5) -> 36 | D15: 4 (Staff) | F15: =1.7*253*4 -> 1720.4 | J15: =SUM(J12:R12) -> 1029224.4
A16: Student Project/Art Display | B16: 98 | C16: =B16*(4.5) -> 441 | D16: 200
A17: Studio | B17: 30 | C17: =B17*(4.5) -> 135 | D17: 10
A20: First Floor
A22: Café | B22: 70 | C22: =B22*4.5 -> 315 | D22: 35
A23: Study Spaces | B23: 300 | C23: =B23*4.5 -> 1350 | D23: 150 | F23: =1.7*365*75 -> 46537.5
A24: Seminar Rooms | B24: 98 | C24: =B24*4.5 -> 441 | D24: 60
A25: Computer Cluster | B25: 112 | C25: =B25*4.5 -> 504 | D25: 65 | F25: =1.7*365*65 -> 40332.5
A26: Lecture Theatre | B26: 98 | C26: =B26*4.5 -> 441 | D26: 100
A27: Study Rooms | B27: 70 | C27: =B27*4.5 -> 315 | D27: 32
A28: Student Common Area | B28: 84 | C28: =B28*4.5 -> 378 | D28: 43
A29: Staff Room | B29: 35 | C29: =B29*4.5 -> 157.5 | D29: 18
A32: Second Floor
A34: Office Space | B34: 936 | C34: =B34*4.5 -> 4212 | D34: 160 | F34: =1.7*253*160 -> 68816 | J34: Assumptions:
A35: Kitchen/Diner | B35: 49 | C35: =B35*4.5 -> 220.5 | D35: 40 | G35: =365*2.2 -> 803 | J35: 1. 40% of max capacity of the library will be computers.
A36: Meeting Rooms | B36: 95 | C36: =B36*4.5 -> 427.5 | D36: 50 | J36: 2. 50% of max capacity of the study spaces will be computers.
A37: Reception Desk | B37: 16 | C37: =B37*4.5 -> 72 | D37: 8 | F37: =1.7*253*8 -> 3440.8 | J37: 3. 25% of max capacity of the R&D dry lab will be computers.
J38: 4. The kitchen/diner will have 2 microwave and 1 fridge.
J39: 5. The café is opened from 8am-4pm-- 8hrs.
A40: Third Floor | J40: 6. Heating will be on from mid sept to mid may.
J41: 7. Cooling will be on from mid may to mid sept.
A42: Office Space | B42: 936 | C42: =B42*4.5 -> 4212 | D42: 160 | F42: =1.7*253*160 -> 68816
A43: Kitchen/Diner | B43: 49 | C43: =B43*4.5 -> 220.5 | D43: 40 | G43: =365*2.2 -> 803 | J43: The numbers are based of these:
A44: Meeting Rooms | B44: 95 | C44: =B44*4.5 -> 427.5 | D44: 50 | J44: Kitchen Appliances:
A45: Reception Desk | B45: 16 | C45: =B45*4.5 -> 72 | D45: 8 | F45: =1.7*253*8 -> 3440.8
A48: Fourth Floor
A50: R&D Wet Lab | B50: 300 | C50: =B50*4.5 -> 1350 | D50: 60
A51: Private Offices | B51: 84 | C51: =B51*4.5 -> 378 | D51: 14 | F51: =1.7*253*14 -> 6021.4
A52: Meeting Pods | B52: 84 | C52: =B52*4.5 -> 378 | D52: 45
A53: Showcase/Demo Room | B53: 49 | C53: =B53*4.5 -> 220.5 | D53: 33 | J53: Ccomputers:
...

Sheet Energy Intervention

Sheet Carbon Emission
A2: The formula below was used to find the baseline and intervention carbon emissions with an Uk's carbon intensity of 238 gCO2/kWh:
A9: Baseline Carbon Emissions:
A10: Lighting | B10: Cooking Equipment | C10: Water Heating | D10: Computers | E10: Heating | F10: Ventilation | G10: Cooling | I10: total
A11: =(406875.9889*238)/1000 -> 96836.485 | B11: =(31966*238)/1000 -> 7607.908 | C11: =(29062.57064*238)/1000 -> 6916.8918 | D11: =(309444.2*238)/1000 -> 73647.72 | E11: =(77500.18837*238)/1000 -> 18445.045 | F11: =(116250.2826*238)/1000 -> 27667.567 | G11: =(58125.14128*238)/1000 -> 13833.784 | I11: =SUM(A11:G11) -> 244955.4
A15: Intervention Carbon Emissions:
A16: Lighting | B16: Cooking Equipment | C16: Water Heating | D16: Computers | E16: Heating | F16: Ventilation | G16: Cooling | I16: total
A17: =(73237.678*238)/1000 -> 17430.567 | B17: =(31966*238)/1000 -> 7607.908 | C17: =(19809.04814*238)/1000 -> 4714.5535 | D17: =(232083.15*238)/1000 -> 55235.79 | E17: =(22709.1052*238)/1000 -> 5404.767 | F17: =(18845.3938*238)/1000 -> 4485.2037 | G17: =(26202.8137*238)/1000 -> 6236.2697 | I17: =SUM(A17:G17) -> 101115.06
A19: Reduction:
A20: =I11-I17 -> 143840.34

Sheet Costs

Sheet Solar Panels 
A1: Area for solar panels and sizing:
A81: Power Generation from the Solar Panels:
